<mujoco><option gravity="0 0 -9.81" /><worldbody><light diffuse="0.8 0.8 0.8" pos="0 0 3" dir="0 0 -1" /><geom size="10 10 .05" type="plane" material="grid" condim="3" /><body name="chassis" pos="0 2 2"><joint type="free" /><geom type="box" size=".1 5 2" rgba=".9 .9 .9 1" mass="100" /><body name="module__0module-top" pos="1 -1 1"><joint type="hinge" axis="1 0 0" range="-45 45" /><geom type="box" name="module__0geom_free_plate" size=".1 .5 .5" rgba="0.9 0 0 1" /><body name="module__0slide_box" pos="1 0.3 0.3"><joint name="module__0slide_box_joint" type="slide" axis="1 0 0" range="-0.5 0.5" /><geom type="box" name="module__0slide_box_body" size="0.5 0.1 0.1" rgba=" 0 0 0 1" /><body name="module__0hingex_box_body" pos="1 0 0"><joint name="module__0hingex_box_joint" type="hinge" axis="1 0 0" range="-45 45" /><geom type="box" name="module__0geom_hingex_box" size="0.5 0.1 0.1" rgba="0.9 0 0 1" /><body name="module__0hingey_box_body" pos="1 0 0"><joint name="module__0hingey_box_joint" type="hinge" axis="0 1 0" range="-45 45" /><geom type="box" name="module__0geom_hingey_box" size="0.5 0.1 0.1" rgba="0.9 0 0 1" /><body name="module__0hingez_box_body" pos="1 0 0"><joint name="module__0hingez_box_joint" type="hinge" axis="0 0 1" range="-45 45" /><geom type="box" name="module__0geom_hingez_box" size="0.5 0.1 0.1" rgba="0.9 0 0 1" /><body name="module__0slide_plate" pos="1 -0.3 -0.3"><joint name="module__0slide_plate_joint" type="slide" range="-0.5 0.5" /><geom type="box" name="module__0slide_plate" size="0.1 .5 .5" rgba="0 0 0 1" /></body></body></body></body></body></body><body name="module__1module-top" pos="0 -3 -1"><joint type="hinge" axis="1 0 0" range="-45 45" /><geom type="box" name="module__1geom_free_plate" size=".1 .5 .5" rgba="0.9 0 0 1" /><body name="module__1slide_box" pos="1 0.3 0.3"><joint name="module__1slide_box_joint" type="slide" axis="1 0 0" range="-0.5 0.5" /><geom type="box" name="module__1slide_box_body" size="0.5 0.1 0.1" rgba=" 0 0 0 1" /><body name="module__1hingex_box_body" pos="1 0 0"><joint name="module__1hingex_box_joint" type="hinge" axis="1 0 0" range="-45 45" /><geom type="box" name="module__1geom_hingex_box" size="0.5 0.1 0.1" rgba="0.9 0 0 1" /><body name="module__1hingey_box_body" pos="1 0 0"><joint name="module__1hingey_box_joint" type="hinge" axis="0 1 0" range="-45 45" /><geom type="box" name="module__1geom_hingey_box" size="0.5 0.1 0.1" rgba="0.9 0 0 1" /><body name="module__1hingez_box_body" pos="1 0 0"><joint name="module__1hingez_box_joint" type="hinge" axis="0 0 1" range="-45 45" /><geom type="box" name="module__1geom_hingez_box" size="0.5 0.1 0.1" rgba="0.9 0 0 1" /><body name="module__1slide_plate" pos="1 -0.3 -0.3"><joint name="module__1slide_plate_joint" type="slide" range="-0.5 0.5" /><geom type="box" name="module__1slide_plate" size="0.1 .5 .5" rgba="0 0 0 1" /><body name="module__2module-top" pos="0 0 0"><joint type="hinge" axis="1 0 0" range="-45 45" /><geom type="box" name="module__2geom_free_plate" size=".1 .5 .5" rgba="0.9 0 0 1" /><body name="module__2slide_box" pos="1 0.3 0.3"><joint name="module__2slide_box_joint" type="slide" axis="1 0 0" range="-0.5 0.5" /><geom type="box" name="module__2slide_box_body" size="0.5 0.1 0.1" rgba=" 0 0 0 1" /><body name="module__2hingex_box_body" pos="1 0 0"><joint name="module__2hingex_box_joint" type="hinge" axis="1 0 0" range="-45 45" /><geom type="box" name="module__2geom_hingex_box" size="0.5 0.1 0.1" rgba="0.9 0 0 1" /><body name="module__2hingey_box_body" pos="1 0 0"><joint name="module__2hingey_box_joint" type="hinge" axis="0 1 0" range="-45 45" /><geom type="box" name="module__2geom_hingey_box" size="0.5 0.1 0.1" rgba="0.9 0 0 1" /><body name="module__2hingez_box_body" pos="1 0 0"><joint name="module__2hingez_box_joint" type="hinge" axis="0 0 1" range="-45 45" /><geom type="box" name="module__2geom_hingez_box" size="0.5 0.1 0.1" rgba="0.9 0 0 1" /><body name="module__2slide_plate" pos="1 -0.3 -0.3"><joint name="module__2slide_plate_joint" type="slide" range="-0.5 0.5" /><geom type="box" name="module__2slide_plate" size="0.1 .5 .5" rgba="0 0 0 1" /><body name="module__3module-top" pos="0 0 0"><joint type="hinge" axis="1 0 0" range="-45 45" /><geom type="box" name="module__3geom_free_plate" size=".1 .5 .5" rgba="0.9 0 0 1" /><body name="module__3slide_box" pos="1 0.3 0.3"><joint name="module__3slide_box_joint" type="slide" axis="1 0 0" range="-0.5 0.5" /><geom type="box" name="module__3slide_box_body" size="0.5 0.1 0.1" rgba=" 0 0 0 1" /><body name="module__3hingex_box_body" pos="1 0 0"><joint name="module__3hingex_box_joint" type="hinge" axis="1 0 0" range="-45 45" /><geom type="box" name="module__3geom_hingex_box" size="0.5 0.1 0.1" rgba="0.9 0 0 1" /><body name="module__3hingey_box_body" pos="1 0 0"><joint name="module__3hingey_box_joint" type="hinge" axis="0 1 0" range="-45 45" /><geom type="box" name="module__3geom_hingey_box" size="0.5 0.1 0.1" rgba="0.9 0 0 1" /><body name="module__3hingez_box_body" pos="1 0 0"><joint name="module__3hingez_box_joint" type="hinge" axis="0 0 1" range="-45 45" /><geom type="box" name="module__3geom_hingez_box" size="0.5 0.1 0.1" rgba="0.9 0 0 1" /><body name="module__3slide_plate" pos="1 -0.3 -0.3"><joint name="module__3slide_plate_joint" type="slide" range="-0.5 0.5" /><geom type="box" name="module__3slide_plate" size="0.1 .5 .5" rgba="0 0 0 1" /></body></body></body></body></body></body><body name="module__4module-top" pos="0 0 0"><joint type="hinge" axis="1 0 0" range="-45 45" /><geom type="box" name="module__4geom_free_plate" size=".1 .5 .5" rgba="0.9 0 0 1" /><body name="module__4slide_box" pos="1 0.3 0.3"><joint name="module__4slide_box_joint" type="slide" axis="1 0 0" range="-0.5 0.5" /><geom type="box" name="module__4slide_box_body" size="0.5 0.1 0.1" rgba=" 0 0 0 1" /><body name="module__4hingex_box_body" pos="1 0 0"><joint name="module__4hingex_box_joint" type="hinge" axis="1 0 0" range="-45 45" /><geom type="box" name="module__4geom_hingex_box" size="0.5 0.1 0.1" rgba="0.9 0 0 1" /><body name="module__4hingey_box_body" pos="1 0 0"><joint name="module__4hingey_box_joint" type="hinge" axis="0 1 0" range="-45 45" /><geom type="box" name="module__4geom_hingey_box" size="0.5 0.1 0.1" rgba="0.9 0 0 1" /><body name="module__4hingez_box_body" pos="1 0 0"><joint name="module__4hingez_box_joint" type="hinge" axis="0 0 1" range="-45 45" /><geom type="box" name="module__4geom_hingez_box" size="0.5 0.1 0.1" rgba="0.9 0 0 1" /><body name="module__4slide_plate" pos="1 -0.3 -0.3"><joint name="module__4slide_plate_joint" type="slide" range="-0.5 0.5" /><geom type="box" name="module__4slide_plate" size="0.1 .5 .5" rgba="0 0 0 1" /></body></body></body></body></body></body></body></body></body></body></body></body></body></body></body></body></body></body></body></worldbody><asset><texture type="skybox" builtin="gradient" rgb1=".3 .5 .7" rgb2="0 0 0" width="512" height="512" /><texture name="body" type="cube" builtin="flat" mark="cross" width="128" height="128" rgb1="0.8 0.6 0.4" rgb2="0.8 0.6 0.4" markrgb="1 1 1" random="0.01" /><texture name="grid" type="2d" builtin="checker" width="512" height="512" rgb1=".1 .2 .3" rgb2=".2 .3 .4" /><material name="body" texture="body" texuniform="true" rgba="0.8 0.6 .4 1" /><material name="grid" texture="grid" texrepeat="1 1" texuniform="true" reflectance=".2" /></asset><actuator><velocity joint="module__0slide_box_joint" kv="2000" /></actuator></mujoco>