<mujoco><option gravity="0 0 -9.81" /><worldbody><light diffuse=".5 .5 .5" pos="0 0 3" dir="0 0 -1" /><geom type="plane" size="5 5 0.1" rgba=".9 .9 .9 1" /><body name="chassis" pos="0 0 0.2" euler="0 90 0"><joint type="free" /><geom type="box" size=".05 .2 .5" rgba="0.9 0 0 1" /><body name="leftf-tire" pos="0 0.3 -0.5" euler="90 0 0"><joint name="leftf-wheel" type="hinge" axis="0 0 -1" /><geom type="cylinder" size=".2 0.05" rgba="0 0 0 1" /><body pos="0 0.2 0" euler="0 0 0"><geom type="cylinder" size=".1 0.05" rgba="1 0 0 1" /></body><body pos="0 -0.2 0" euler="0 0 0"><geom type="cylinder" size=".1 0.05" rgba="1 0 0 1" /></body><body pos="0.2 0 0" euler="0 0 0"><geom type="cylinder" size=".1 0.05" rgba="1 0 0 1" /></body><body pos="-0.2 0 0" euler="0 0 0"><geom type="cylinder" size=".1 0.05" rgba="1 0 0 1" /></body></body><body name="leftb-tire" pos="0 0.3 0.5" euler="90 0 0"><joint name="leftb-wheel" type="hinge" axis="0 0 -1" /><geom type="cylinder" size=".2 0.05" rgba="0 0 0 1" /><body pos="0 0.2 0" euler="0 0 0"><geom type="cylinder" size=".1 0.05" rgba="1 0 0 1" /></body><body pos="0 -0.2 0" euler="0 0 0"><geom type="cylinder" size=".1 0.05" rgba="1 0 0 1" /></body><body pos="0.2 0 0" euler="0 0 0"><geom type="cylinder" size=".1 0.05" rgba="1 0 0 1" /></body><body pos="-0.2 0 0" euler="0 0 0"><geom type="cylinder" size=".1 0.05" rgba="1 0 0 1" /></body></body><body name="rightf-tire" pos="0 -0.3 -0.5" euler="90 0 0"><joint name="rightf-wheel" type="hinge" axis="0 0 -1" /><geom type="cylinder" size=".2 0.05" rgba="0 0 0 1" /><body pos="0 0.2 0" euler="0 0 0"><geom type="cylinder" size=".1 0.05" rgba="1 0 0 1" /></body><body pos="0 -0.2 0" euler="0 0 0"><geom type="cylinder" size=".1 0.05" rgba="1 0 0 1" /></body><body pos="0.2 0 0" euler="0 0 0"><geom type="cylinder" size=".1 0.05" rgba="1 0 0 1" /></body><body pos="-0.2 0 0" euler="0 0 0"><geom type="cylinder" size=".1 0.05" rgba="1 0 0 1" /></body></body><body name="rightb-tire" pos="0 -0.3 0.5" euler="90 0 0"><joint name="rightb-wheel" type="hinge" axis="0 0 -1" /><geom type="cylinder" size=".2 0.05" rgba="0 0 0 1" /><body pos="0 0.2 0" euler="0 0 0"><geom type="cylinder" size=".1 0.05" rgba="1 0 0 1" /></body><body pos="0 -0.2 0" euler="0 0 0"><geom type="cylinder" size=".1 0.05" rgba="1 0 0 1" /></body><body pos="0.2 0 0" euler="0 0 0"><geom type="cylinder" size=".1 0.05" rgba="1 0 0 1" /></body><body pos="-0.2 0 0" euler="0 0 0"><geom type="cylinder" size=".1 0.05" rgba="1 0 0 1" /></body></body></body></worldbody><actuator><velocity name="leftf-velocity-servo" joint="leftf-wheel" kv="100" /><velocity name="leftb-velocity-servo" joint="leftb-wheel" kv="100" /><velocity name="rightf-velocity-servo" joint="rightf-wheel" kv="100" /><velocity name="rightb-velocity-servo" joint="rightb-wheel" kv="100" /></actuator></mujoco>