<mujoco><option gravity="0 0 -9.81" /><worldbody><light diffuse="0.8 0.8 0.8" pos="0 0 3" dir="0 0 -1" /><geom size="10 10 .05" type="plane" material="grid" condim="3" /><body name="chassis" pos="2 2 2"><joint type="free" /><geom type="box" size=".1 2 1" rgba=".9 .9 .9 1" /><body name="module1module-top" pos="1 -1 1"><joint type="hinge" axis="1 0 0" range="-45 45" /><geom type="box" name="module1geom_free_plate" size=".1 1 1" rgba="0.9 0 0 1" /><body name="module1slide_box" pos="1 0.3 0.3"><joint name="module1slide_box_joint" type="slide" axis="1 0 0" range="-0.5 0.5" /><geom type="box" name="module1slide_box_body" size="0.5 0.1 0.1" rgba=" 0 0 0 1" /><body name="module1hingex_box_body" pos="1 0 0"><joint name="module1hingex_box_joint" type="hinge" axis="1 0 0" range="-45 45" /><geom type="box" name="module1hingex_box_body" size="0.5 0.1 0.1" rgba="0.9 0 0 1" /><body name="module1hingey_box_body" pos="1 0 0"><joint name="module1hingey_box_joint" type="hinge" axis="0 1 0" range="-45 45" /><geom type="box" name="module1geom_hingey_box" size="0.5 0.1 0.1" rgba="0.9 0 0 1" /><body name="module1hingez_box_body" pos="1 0 0"><joint name="module1hingez_box_joint" type="hinge" axis="0 0 1" range="-45 45" /><geom type="box" name="module1geom_hingez_box" size="0.5 0.1 0.1" rgba="0.9 0 0 1" /><body name="module1slide_plate" pos="1 -0.3 -0.3"><joint name="module1slide_plate_joint" type="slide" range="-0.5 0.5" /><geom type="box" name="module1slide_plate" size="0.1 1 1" rgba="0 0 0 1" /></body></body></body></body></body></body><body name="module2module-top" pos="1 1 1"><joint type="hinge" axis="1 0 0" range="-45 45" /><geom type="box" name="module2geom_free_plate" size=".1 1 1" rgba="0.9 0 0 1" /><body name="module2slide_box" pos="1 0.3 0.3"><joint name="module2slide_box_joint" type="slide" axis="1 0 0" range="-0.5 0.5" /><geom type="box" name="module2slide_box_body" size="0.5 0.1 0.1" rgba=" 0 0 0 1" /><body name="module2hingex_box_body" pos="1 0 0"><joint name="module2hingex_box_joint" type="hinge" axis="1 0 0" range="-45 45" /><geom type="box" name="module2hingex_box_body" size="0.5 0.1 0.1" rgba="0.9 0 0 1" /><body name="module2hingey_box_body" pos="1 0 0"><joint name="module2hingey_box_joint" type="hinge" axis="0 1 0" range="-45 45" /><geom type="box" name="module2geom_hingey_box" size="0.5 0.1 0.1" rgba="0.9 0 0 1" /><body name="module2hingez_box_body" pos="1 0 0"><joint name="module2hingez_box_joint" type="hinge" axis="0 0 1" range="-45 45" /><geom type="box" name="module2geom_hingez_box" size="0.5 0.1 0.1" rgba="0.9 0 0 1" /><body name="module2slide_plate" pos="1 -0.3 -0.3"><joint name="module2slide_plate_joint" type="slide" range="-0.5 0.5" /><geom type="box" name="module2slide_plate" size="0.1 1 1" rgba="0 0 0 1" /></body></body></body></body></body></body></body></worldbody><asset><texture type="skybox" builtin="gradient" rgb1=".3 .5 .7" rgb2="0 0 0" width="512" height="512" /><texture name="body" type="cube" builtin="flat" mark="cross" width="128" height="128" rgb1="0.8 0.6 0.4" rgb2="0.8 0.6 0.4" markrgb="1 1 1" random="0.01" /><texture name="grid" type="2d" builtin="checker" width="512" height="512" rgb1=".1 .2 .3" rgb2=".2 .3 .4" /><material name="body" texture="body" texuniform="true" rgba="0.8 0.6 .4 1" /><material name="grid" texture="grid" texrepeat="1 1" texuniform="true" reflectance=".2" /></asset><actuator><velocity joint="module1slide_box_joint" kv="2000" /></actuator></mujoco>